<?xml version="1.0"?>
<robot name="eco">

    <gazebo>
        <plugin name="gazebo_ros_control" filename="libgazebo_ros_control.so">
            <robotNamespace>/eco</robotNamespace>
        </plugin>
    </gazebo>


    <link name="hold_link">
        <inertial>
            <origin xyz="0 0 0" rpy="0 0 0"/>
            <mass value="10" />
            <inertia ixx="0.075" ixy="0.0" ixz="0.0" iyy="0.075" iyz="0.0" izz="0.1125"/>
        </inertial>

        <collision>
            <origin xyz="0 0 0" rpy="0 0 0"/>
            <geometry>
                <cylinder length="0.15" radius="0.15"/>
            </geometry>
        </collision>

        <visual>
            <origin rpy="0.0 0 0" xyz="0 0 0"/>
            <geometry>
                <cylinder length="0.15" radius="0.15"/>
            </geometry>
        </visual>
    </link>

    <gazebo reference="hold_link">
        <material>Gazebo/Wood</material>
    </gazebo>

    <link name="base_link">
        <inertial>
            <origin xyz="0 0 0.9" rpy="0 0 0"/>
            <mass value="2.25" />
            <inertia ixx="0.60796875" ixy="0.0" ixz="0.0" iyy="0.60796875" iyz="0.0" izz="0.0009375"/>
        </inertial>

        <collision>
            <origin xyz="0 0 0.9" rpy="0 0 0"/>
            <geometry>
                <box size="0.05 0.05 1.8"/>
            </geometry>
        </collision>

        <visual>
            <origin rpy="0.0 0 0" xyz="0 0 0.9"/>
            <geometry>
                <box size="0.05 0.05 1.8"/>
            </geometry>
        </visual>
    </link>

    <gazebo reference="base_link">
        <material>Gazebo/Wood</material>
    </gazebo>


    <joint name="hold_joint" type="revolute">
        <parent link="hold_link"/>
        <child link="base_link"/>
        <origin xyz="0 0 0" rpy="0 0 0"/>
        <limit lower="0" upper="0" effort="0" velocity="0"/>
        <axis xyz="0 0 0"/>
    </joint>

    <transmission name="tran1">
        <type>transmission_interface/SimpleTransmission</type>
        <joint name="hold_joint">
            <hardwareInterface>EffortJointInterface</hardwareInterface>
        </joint>
        <actuator name="motor1">
            <hardwareInterface>EffortJointInterface</hardwareInterface>
            <mechanicalReduction>1</mechanicalReduction>
        </actuator>
    </transmission>


    <link name="plank_link">
        <inertial>
            <origin xyz="0 1.725 0" rpy="0 0 0"/>
            <mass value="4.0" />
            <inertia ixx="2.08416666667" ixy="0.0" ixz="0.0" iyy="0.00166666666667" iyz="0.0" izz="2.08416666667"/>
        </inertial>

        <collision>
            <origin xyz="0 1.725 0" rpy="0 0 0"/>
            <geometry>
                <box size="0.05 3.5 0.05"/>
            </geometry>
        </collision>

        <visual>
            <origin rpy="0.0 0 0" xyz="0 1.725 0"/>
            <geometry>
                <box size="0.05 3.5 0.05"/>
            </geometry>
        </visual>
        
    </link>

    <gazebo reference="plank_link">
        <material>Gazebo/Grey</material>
    </gazebo>

    <joint name="base_joint" type="revolute">
        <parent link="base_link"/>
        <child link="plank_link"/>
        <origin xyz="0 0 1.8" rpy="0 0 0"/>
        <limit lower="0" upper="0" effort="0" velocity="0"/>
        <axis xyz="0 0 0"/>
    </joint>

    <transmission name="tran2">
        <type>transmission_interface/SimpleTransmission</type>
        <joint name="base_joint">
            <hardwareInterface>EffortJointInterface</hardwareInterface>
        </joint>
        <actuator name="motor2">
            <hardwareInterface>EffortJointInterface</hardwareInterface>
            <mechanicalReduction>1</mechanicalReduction>
        </actuator>
    </transmission>

    <link name="base2_link">
        <inertial>
            <origin xyz="0 0 -0.9" rpy="0 0 0"/>
            <mass value="2.25" />
            <inertia ixx="0.60796875" ixy="0.0" ixz="0.0" iyy="0.60796875" iyz="0.0" izz="0.0009375"/>
        </inertial>

        <collision>
            <origin xyz="0 0 -0.9" rpy="0 0 0"/>
            <geometry>
                <box size="0.05 0.05 1.8"/>
            </geometry>
        </collision>

        <visual>
            <origin rpy="0.0 0 0" xyz="0 0 -0.9"/>
            <geometry>
                <box size="0.05 0.05 1.8"/>
            </geometry>
        </visual>

    </link>

    <gazebo reference="base2_link">
        <material>Gazebo/Wood</material>
    </gazebo>

    <joint name="base2_joint" type="revolute">
        <parent link="plank_link"/>
        <child link="base2_link"/>
        <origin xyz="0 3.45 0" rpy="0 0 0"/>
        <limit lower="0" upper="0" effort="0" velocity="0"/>
        <axis xyz="0 0 0"/>
    </joint>

    <transmission name="tran3">
        <type>transmission_interface/SimpleTransmission</type>
        <joint name="base2_joint">
            <hardwareInterface>EffortJointInterface</hardwareInterface>
        </joint>
        <actuator name="motor3">
            <hardwareInterface>EffortJointInterface</hardwareInterface>
            <mechanicalReduction>1</mechanicalReduction>
        </actuator>
    </transmission>

    <link name="hold2_link">
        <inertial>
            <origin xyz="0 0 0" rpy="0 0 0"/>
            <mass value="10" />
            <inertia ixx="0.075" ixy="0.0" ixz="0.0" iyy="0.075" iyz="0.0" izz="0.1125"/>
        </inertial>

        <collision>
            <origin xyz="0 0 0" rpy="0 0 0"/>
            <geometry>
                <cylinder length="0.15" radius="0.15"/>
            </geometry>
        </collision>

        <visual>
            <origin rpy="0.0 0 0" xyz="0 0 0"/>
            <geometry>
                <cylinder length="0.15" radius="0.15"/>
            </geometry>
        </visual>
    </link>

    <gazebo reference="hold2_link">
        <material>Gazebo/Wood</material>
    </gazebo>

    <joint name="hold2_joint" type="revolute">
        <parent link="base2_link"/>
        <child link="hold2_link"/>
        <origin xyz="0 0 -1.8" rpy="0 0 0"/>
        <limit lower="0" upper="0" effort="0" velocity="0"/>
        <axis xyz="0 0 0"/>
    </joint>

    <transmission name="tran4">
        <type>transmission_interface/SimpleTransmission</type>
        <joint name="hold2_joint">
            <hardwareInterface>EffortJointInterface</hardwareInterface>
        </joint>
        <actuator name="motor4">
            <hardwareInterface>EffortJointInterface</hardwareInterface>
            <mechanicalReduction>1</mechanicalReduction>
        </actuator>
    </transmission>

    <link name="shift_link">
        <inertial>
            <origin xyz="0 0 0" rpy="0 0 0"/>
            <mass value="1.5" />
            <inertia ixx="0.005625" ixy="0.0" ixz="0.0" iyy="0.005625" iyz="0.0" izz="0.005625"/>
        </inertial>

        <collision>
            <origin xyz="0 0 0" rpy="0 0 0"/>
            <geometry>
                <box size="0.15 0.15 0.15"/>
            </geometry>
        </collision>

        <visual>
            <origin rpy="0.0 0 0" xyz="0 0 0"/>
            <geometry>
                <box size="0.15 0.15 0.15"/>
            </geometry>
        </visual>
    </link>

   

    <joint name="shift_joint" type="prismatic">
        <parent link="plank_link"/>
        <child link="shift_link"/>
        <origin xyz="0 0.1 0" rpy="0 0 0"/>
        <limit effort="60" velocity="70" lower="0" upper="1.25"/>
        <axis xyz="0 1 0"/>    
    </joint>

    <gazebo reference="shift_link">
        <dampingFactor>0.1</dampingFactor>
        <material>Gazebo/Grey</material>
    </gazebo>

    <transmission name="tran5">
        <type>transmission_interface/SimpleTransmission</type>
        <joint name="shift_joint">
            <hardwareInterface>EffortJointInterface</hardwareInterface>
        </joint>
        <actuator name="motor5">
            <hardwareInterface>EffortJointInterface</hardwareInterface>
            <mechanicalReduction>1</mechanicalReduction>
        </actuator>
    </transmission>

    <link name="lift_link">
        <inertial>
            <origin xyz="0 0 -0.4" rpy="1.57 0 0"/>
            <mass value="0.4" />
            <inertia ixx="0.0213633333333" ixy="0.0" ixz="0.0" iyy="6e-05" iyz="0.0" izz="0.0213633333333"/>
        </inertial>

        <collision>
            <origin xyz="0 0 -0.4" rpy="1.57 0 0"/>
            <geometry>
                <box size="0.03 0.8 0.03"/>
            </geometry>
        </collision>

        <visual>
            <origin xyz="0 0 -0.4" rpy="1.57 0 0"/>
            <geometry>
                <box size="0.03 0.8 0.03"/>
            </geometry>
        </visual>
        
    </link>

    <gazebo reference="lift_link">
        <material>Gazebo/Grey</material>
    </gazebo>

    <joint name="lift_joint" type="prismatic">
        <parent link="shift_link"/>
        <child link="lift_link"/>
        <origin xyz="0 0 0" rpy="0 0 0"/>
        <limit effort="80" velocity="40" lower="0" upper="0.7"/>
        <axis xyz="0 0 1"/>
    </joint>

    <transmission name="tran6">
        <type>transmission_interface/SimpleTransmission</type>
        <joint name="lift_joint">
            <hardwareInterface>EffortJointInterface</hardwareInterface>
        </joint>
        <actuator name="motor6">
            <hardwareInterface>EffortJointInterface</hardwareInterface>
            <mechanicalReduction>1</mechanicalReduction>
        </actuator>
    </transmission>

    <link name="base_arm_link">
        <inertial>
            <origin xyz="0 0 0" rpy="0 0 0"/>
            <mass value="0.4" />
            <inertia ixx="0.000533333333333" ixy="0.0" ixz="0.0" iyy="0.000533333333333" iyz="0.0" izz="0.00096"/>
        </inertial>

        <collision>
            <origin xyz="0 0 0" rpy="0 0 0"/>
            <geometry>
                <box size="0.12 0.12 0.04"/>
            </geometry>
        </collision>

        <visual>
            <origin xyz="0 0 0" rpy="0 0 0"/>
            <geometry>
                <box size="0.12 0.12 0.04"/>
            </geometry>
        </visual>
        
    </link>

    <gazebo reference="base_arm_link">
        <material>Gazebo/Wood</material>
    </gazebo>

    <joint name="base_arm_joint" type="revolute">
        <parent link="lift_link"/>
        <child link="base_arm_link"/>
        <origin xyz="0 0 -0.8" rpy="0 0 0"/>
        <limit lower="0" upper="0" effort="0" velocity="0"/>
        <axis xyz="0 0 0"/>
    </joint>

    <transmission name="tran7">
        <type>transmission_interface/SimpleTransmission</type>
        <joint name="base_arm_joint">
            <hardwareInterface>EffortJointInterface</hardwareInterface>
        </joint>
        <actuator name="motor7">
            <hardwareInterface>EffortJointInterface</hardwareInterface>
            <mechanicalReduction>1</mechanicalReduction>
        </actuator>
    </transmission>

    <link name="finger1_link">
        <inertial>
            <origin xyz="0 0 -0.05" rpy="0 0 0"/>
            <mass value="0.1" />
            <inertia ixx="6.14333333333e-05" ixy="0.0" ixz="0.0" iyy="6.14333333333e-05" iyz="0.0" izz="2.45e-06"/>
        </inertial>

        <collision>
            <origin xyz="0 0 -0.05" rpy="0 0 0"/>
            <geometry>
                <cylinder length="0.085" radius="0.007"/>
            </geometry>
        </collision>

        <visual>
            <origin xyz="0 0 -0.05" rpy="0 0 0"/>
            <geometry>
                <cylinder length="0.085" radius="0.007"/>
            </geometry>
        </visual>
    </link>

   

    <joint name="finger1_joint" type="revolute">
        <parent link="base_arm_link"/>
        <child link="finger1_link"/>
        <origin xyz="0.02 0.02 0" rpy="3.14 0 0.78"/>
        <limit lower="-3.5" upper="-1" effort="0.1" velocity="0.005"/>
        <axis xyz="0 1 0"/>
    </joint>

    <gazebo reference="finger1_link">
        <dampingFactor>0.</dampingFactor>
        <minDepth>3</minDepth>  
        <maxVel>0</maxVel>
        <kp>1000000.0</kp>
        <kd>10000.0</kd>
        <mu1>1000.0</mu1>
        <mu2>1000.0</mu2>
        <material>Gazebo/Grey</material>
    </gazebo>

    <transmission name="tran8">
        <type>transmission_interface/SimpleTransmission</type>
        <joint name="finger1_joint">
            <hardwareInterface>EffortJointInterface</hardwareInterface>
        </joint>
        <actuator name="motor8">
            <hardwareInterface>EffortJointInterface</hardwareInterface>
            <mechanicalReduction>1</mechanicalReduction>
        </actuator>
    </transmission>


    <link name="finger2_link">
        <inertial>
            <origin xyz="0 0 -0.05" rpy="0 0 0"/>
            <mass value="0.1" />
            <mass value="0.1" />
            <inertia ixx="6.14333333333e-05" ixy="0.0" ixz="0.0" iyy="6.14333333333e-05" iyz="0.0" izz="2.45e-06"/>
        </inertial>

        <collision>
            <origin xyz="0 0 -0.05" rpy="0 0 0"/>
            <geometry>
                <cylinder length="0.085" radius="0.007"/>
            </geometry>
        </collision>

        <visual>
            <origin xyz="0 0 -0.05" rpy="0 0 0"/>
            <geometry>
                <cylinder length="0.085" radius="0.007"/>
            </geometry>
        </visual>
    </link>



    <joint name="finger2_joint" type="revolute">
        <parent link="base_arm_link"/>
        <child link="finger2_link"/>
        <origin xyz="-0.02 0.02 0" rpy="0 3.14 0.78"/>
        <limit lower="1" upper="5" effort="0.1" velocity="0.005"/>
        <axis xyz="1 0 0"/>
    </joint>

    <gazebo reference="finger2_link">
        <dampingFactor>0.</dampingFactor>
        <minDepth>3</minDepth>  
        <maxVel>0</maxVel>
        <kp>1000000.0</kp>
        <kd>10000.0</kd>
        <mu1>1000.0</mu1>
        <mu2>1000.0</mu2>
        <material>Gazebo/Grey</material>
    </gazebo>

    <transmission name="tran9">
        <type>transmission_interface/SimpleTransmission</type>
        <joint name="finger2_joint">
            <hardwareInterface>EffortJointInterface</hardwareInterface>
        </joint>
        <actuator name="motor9">
            <hardwareInterface>EffortJointInterface</hardwareInterface>
            <mechanicalReduction>1</mechanicalReduction>
        </actuator>
    </transmission>

    <link name="finger3_link">
        <inertial>
            <origin xyz="0 0 -0.05" rpy="0 0 0"/>
            <mass value="0.1" />
            <mass value="0.1" />
            <inertia ixx="6.14333333333e-05" ixy="0.0" ixz="0.0" iyy="6.14333333333e-05" iyz="0.0" izz="2.45e-06"/>
        </inertial>

        <collision>
            <origin xyz="0 0 -0.05" rpy="0 0 0"/>
            <geometry>
                <cylinder length="0.085" radius="0.007"/>
            </geometry>
        </collision>

        <visual>
            <origin xyz="0 0 -0.05" rpy="0 0 0"/>
            <geometry>
                <cylinder length="0.085" radius="0.007"/>
            </geometry>
        </visual>
    </link>

    

    <joint name="finger3_joint" type="revolute">
        <parent link="base_arm_link"/>
        <child link="finger3_link"/>
        <origin xyz="0.02 -0.02 0" rpy="3.14 0 0.78"/>
        <limit lower="-5" upper="-1" effort="0.1" velocity="0.005"/>
        <axis xyz="1 0 0"/>
    </joint>

    <gazebo reference="finger3_link">
        <dampingFactor>0.</dampingFactor>
        <minDepth>3</minDepth>  
        <maxVel>0</maxVel>
        <kp>1000000.0</kp>
        <kd>10000.0</kd>
        <mu1>1000.0</mu1>
        <mu2>1000.0</mu2>
        <material>Gazebo/Grey</material>
    </gazebo>

    <transmission name="tran10">
        <type>transmission_interface/SimpleTransmission</type>
        <joint name="finger3_joint">
            <hardwareInterface>EffortJointInterface</hardwareInterface>
        </joint>
        <actuator name="motor10">
            <hardwareInterface>EffortJointInterface</hardwareInterface>
            <mechanicalReduction>1</mechanicalReduction>
        </actuator>
    </transmission>

    <link name="finger4_link">
        <inertial>
            <origin xyz="0 0 -0.05" rpy="0 0 0"/>
            <mass value="0.1" />
            <mass value="0.1" />
            <inertia ixx="6.14333333333e-05" ixy="0.0" ixz="0.0" iyy="6.14333333333e-05" iyz="0.0" izz="2.45e-06"/>
        </inertial>

        <collision>
            <origin xyz="0 0 -0.05" rpy="0 0 0"/>
            <geometry>
                <cylinder length="0.085" radius="0.007"/>
            </geometry>
        </collision>

        <visual>
            <origin xyz="0 0 -0.05" rpy="0 0 0"/>
            <geometry>
                <cylinder length="0.085" radius="0.007"/>
            </geometry>
        </visual>
    </link>

    

    <joint name="finger4_joint" type="revolute">
        <parent link="base_arm_link"/>
        <child link="finger4_link"/>
        <origin xyz="-0.02 -0.02 0" rpy="3.14 0 0.78"/>
        <limit lower="1" upper="3.5" effort="0.1" velocity="0.005"/>
        <axis xyz="0 1 0"/>
    </joint>

    <gazebo reference="finger4_link">
        <dampingFactor>0.</dampingFactor>
        <minDepth>3</minDepth>  
        <maxVel>0</maxVel>
        <kp>1000000.0</kp>
        <kd>10000.0</kd>
        <mu1>1000.0</mu1>
        <mu2>1000.0</mu2>
        <material>Gazebo/Grey</material>
    </gazebo>

    <transmission name="tran11">
        <type>transmission_interface/SimpleTransmission</type>
        <joint name="finger4_joint">
            <hardwareInterface>EffortJointInterface</hardwareInterface>
        </joint>
        <actuator name="motor11">
            <hardwareInterface>EffortJointInterface</hardwareInterface>
            <mechanicalReduction>1</mechanicalReduction>
        </actuator>
    </transmission>

    <link name="camera_link">
        <inertial>
            <origin xyz="0 0 0" rpy="0 0 0"/>
            <mass value="0.001" />
            <inertia ixx="9.1875e-09" ixy="0.0" ixz="0.0" iyy="9.1875e-09" iyz="0.0" izz="1.378125e-08"/>
        </inertial>

        <collision>
            <origin xyz="0 0 0" rpy="0 0 0"/>
            <geometry>
                <box size="0.0005 0.0005 0.0005"/>
            </geometry>
        </collision>

        <visual>
            <origin xyz="0 0 0" rpy="0 0 0"/>
            <geometry>
                <box size="0.0005 0.0005 0.0005"/>
            </geometry>
            <material name="red"/>
        </visual>
        <static>true</static>
    </link>

    <gazebo reference="camera_link">
        <material>Gazebo/Red</material>
        <static>true</static>
    </gazebo>


    <joint name="camera_joint" type="revolute">
        <parent link="plank_link"/>
        <child link="camera_link"/>
        <origin xyz="0.75 1.75 0" rpy="0 1.5708 0"/>
        <limit lower="0" upper="0" effort="0" velocity="0"/>
        <axis xyz="0 1 0"/>
        <static>true</static>
    </joint>

    <gazebo reference="camera_joint">
        <static>true</static>
    </gazebo>

    <!-- camera -->
  <gazebo reference="camera_link">
    <sensor type="camera" name="camera1">
      <update_rate>1</update_rate>
      <camera name="camera1">

          <pose>0 0 0 0 0 0</pose>

        <horizontal_fov>0.7</horizontal_fov>
        <image>
          <width>400</width>
          <height>400</height>
          <format>R8G8B8</format>
        </image>
        <clip>
          <near>0.01</near>
          <far>100</far>
        </clip>
      </camera>
      <plugin name="camera_controller" filename="libgazebo_ros_camera.so">
        <alwaysOn>true</alwaysOn>
        <updateRate>0.0</updateRate>
        <cameraName>eco/camera1</cameraName>
        <imageTopicName>image_raw</imageTopicName>
        <cameraInfoTopicName>camera_info</cameraInfoTopicName>
        <frameName>camera_link</frameName>
        <hackBaseline>0.0</hackBaseline>
        <distortionK1>0.0</distortionK1>
        <distortionK2>0.0</distortionK2>
        <distortionK3>0.0</distortionK3>
        <distortionT1>0.0</distortionT1>
        <distortionT2>0.0</distortionT2>
      </plugin>
      <visualize>true</visualize>
    </sensor>
  </gazebo>

</robot>